<?xml version="1.0"?>
<robot name="QCar" xmlns:xacro="http://www.ros.org/wiki/xacro">
  <xacro:macro name="QCar" params="prefix *origin">
    <!-- includes (ROS 2 Humble style) -->
    <xacro:include filename="qcar.gazebo.xacro"/>
    <xacro:include filename="qcar.materials.xacro"/>

    <!-- Degree-to-radian conversions -->
    <xacro:property name="degrees_30" value="0.523599"/>
    <xacro:property name="degrees_45" value="0.785398163"/>
    <xacro:property name="degrees_90" value="1.57079633"/>

    <!-- chassis params -->
    <xacro:property name="chassis_length" value="0.425"/>
    <xacro:property name="chassis_width" value="0.192"/>
    <xacro:property name="chassis_height" value="0.182"/>
    <xacro:property name="chassis_mass" value="2.552"/>

    <!-- wheel params -->
    <xacro:property name="hub_dia" value="0.015"/>
    <xacro:property name="tire_dia" value="0.053"/>
    <xacro:property name="tire_width" value="0.025"/>
    <xacro:property name="hex_hub_depth" value="0.018"/>
    <xacro:property name="wheel_mass" value="0.035"/>

    <!-- misc params -->
    <xacro:property name="wheelbase" value="0.265"/>
    <xacro:property name="hex_hub_dist" value="0.285"/>
    <xacro:property name="axle_length" value="0.025"/>
    <xacro:property name="axle_eff_limit" value="5.12766"/>
    <xacro:property name="axle_vel_limit" value="244.8696"/>
    <xacro:property name="servo_stall_torque" value="0.5649"/>
    <xacro:property name="servo_no_load_speed" value="4.553"/>
    <xacro:property name="ctrl_period" value="0.01"/>

    <!-- helper macros -->
    <xacro:macro name="null_inertial">
      <inertial>
        <origin rpy="0 0 0" xyz="0 0 0"/>
        <mass value="0.001"/>
        <inertia ixx="0.001" ixy="0" ixz="0" iyy="0.001" iyz="0" izz="0.001"/>
      </inertial>
    </xacro:macro>

    <xacro:macro name="solid_cuboid_inertial" params="width depth height mass *origin">
      <inertial>
        <xacro:insert_block name="origin"/>
        <mass value="${mass}"/>
        <inertia ixx="${mass * (depth * depth + height * height) / 12}"
                 ixy="0" ixz="0"
                 iyy="${mass * (width * width + height * height) / 12}"
                 iyz="0"
                 izz="${mass * (width * width + depth * depth) / 12}"/>
      </inertial>
    </xacro:macro>

    <xacro:macro name="thick_walled_tube_inertial" params="inner_rad outer_rad height mass">
      <inertial>
        <mass value="${mass}"/>
        <inertia ixx="${(1 / 12) * mass * (3 * (inner_rad * inner_rad + outer_rad * outer_rad) + height * height)}"
                 ixy="0" ixz="0"
                 iyy="${(1 / 12) * mass * (3 * (inner_rad * inner_rad + outer_rad * outer_rad) + height * height)}"
                 iyz="0"
                 izz="${mass * (inner_rad * inner_rad + outer_rad * outer_rad) / 2}"/>
      </inertial>
    </xacro:macro>

    <!-- Root link for RViz (no joint to 'world') -->
    <link name="${prefix}base_link"/>

    <!-- Chassis -->
    <link name="base">
      <visual>
        <origin rpy="0 0 0" xyz="0 0 0"/>
        <geometry>
          <mesh filename="package://qcar_description/meshes/QCarBody.stl" scale="0.001 0.001 0.001"/>
        </geometry>
      </visual>
      <collision>
        <origin rpy="0 0 0" xyz="0 0 0"/>
        <geometry>
          <mesh filename="package://qcar_description/meshes/QCarBody.stl" scale="0.001 0.001 0.001"/>
        </geometry>
      </collision>
      <xacro:solid_cuboid_inertial
        width="${chassis_length}" depth="${chassis_width}"
        height="${chassis_height}" mass="${chassis_mass}">
        <origin xyz="0 0 0"/>
      </xacro:solid_cuboid_inertial>
    </link>

    <!-- base_link -> base -->
    <joint name="base_link_to_chasis" type="fixed">
      <parent link="${prefix}base_link"/>
      <child link="base"/>
    </joint>

    <!-- Sensors -->
    <joint name="body_lidar_joint" type="continuous">
      <parent link="base"/>
      <child link="lidar"/>
      <origin rpy="0 0 0" xyz="-0.01227 -0.00045 0.16152"/>
      <axis xyz="0 0 1"/>
    </joint>
    <link name="lidar">
      <visual>
        <origin rpy="0 0 0" xyz="0 0 0"/>
        <geometry>
          <mesh filename="package://qcar_description/meshes/QCarLidar.stl" scale="0.001 0.001 0.001"/>
        </geometry>
        <material name="blue"/>
      </visual>
      <collision>
        <origin rpy="0 0 0" xyz="0 0 0"/>
        <geometry>
          <mesh filename="package://qcar_description/meshes/QCarLidar.stl" scale="0.001 0.001 0.001"/>
        </geometry>
      </collision>
      <inertial>
        <origin rpy="0 0 0" xyz="0 0 0"/>
        <mass value="0.1"/>
        <inertia ixx="0.001" ixy="0" ixz="0" iyy="0.001" iyz="0" izz="0.001"/>
      </inertial>
    </link>

    <joint name="camera_rgb_joint" type="fixed">
      <origin rpy="0 0 0" xyz="0.081686 0.031547 0.15445"/>
      <parent link="base"/>
      <child link="camera_rgb"/>
    </joint>
    <link name="camera_rgb"/>

    <joint name="camera_csi_front_joint" type="fixed">
      <origin rpy="0 0 0" xyz="0.19236 -0.000475 0.093029"/>
      <parent link="base"/>
      <child link="camera_csi_front"/>
    </joint>
    <link name="camera_csi_front"/>

    <joint name="camera_csi_right_joint" type="fixed">
      <origin rpy="0 0 -1.5708" xyz="0.12887 -0.06755 0.093029"/>
      <parent link="base"/>
      <child link="camera_csi_right"/>
    </joint>
    <link name="camera_csi_right"/>

    <joint name="camera_csi_back_joint" type="fixed">
      <origin rpy="0 0 -3.1416" xyz="-0.16669 -0.000578 0.093029"/>
      <parent link="base"/>
      <child link="camera_csi_back"/>
    </joint>
    <link name="camera_csi_back"/>

    <joint name="camera_csi_left_joint" type="fixed">
      <origin rpy="0 0 1.5708" xyz="0.12784 0.052497 0.093029"/>
      <parent link="base"/>
      <child link="camera_csi_left"/>
    </joint>
    <link name="camera_csi_left"/>

    <!-- Front-left assembly -->
    <joint name="left_front_position_joint" type="fixed">
      <parent link="base"/>
      <child link="left_steering_link"/>
      <origin rpy="0 0 0" xyz="0.12960 0.05590 0.03338"/>
      <axis xyz="0 0 1" />
    </joint>

    <link name="left_steering_link">
      <xacro:null_inertial/>
      <visual>
        <origin rpy="0 0 0" xyz="0 0 0"/>
        <geometry>
          <mesh filename="package://qcar_description/meshes/QCarSteeringHubL.stl" scale="0.001 0.001 0.001"/>
        </geometry>
        <material name="orange"/>
      </visual>
      <collision>
        <origin rpy="0 0 0" xyz="0 0 0"/>
        <geometry>
          <mesh filename="package://qcar_description/meshes/QCarSteeringHubL.stl" scale="0.001 0.001 0.001"/>
        </geometry>
      </collision>
    </link>

    <joint name="left_steering_joint" type="revolute">
      <parent link="left_steering_link"/>
      <child link="left_front_axle_carrier"/>
      <axis xyz="0 0 1"/>
      <limit lower="-0.523599" upper="0.523599" effort="0.5649" velocity="4.553"/>
    </joint>

    <link name="left_front_axle_carrier">
      <xacro:null_inertial/>
    </link>

    <joint name="left_front_axle" type="continuous">
      <parent link="left_front_axle_carrier"/>
      <child link="left_front_wheel"/>
      <axis xyz="0 -1 0"/>
      <origin rpy="0 0 3.14159"/>
      <limit effort="5.12766" velocity="244.8696"/>
      <dynamics damping="0.1" friction="0.1"/>
    </joint>
    <transmission name="left_front_axle_trans">
      <type>transmission_interface/SimpleTransmission</type>
      <joint name="left_front_axle">
        <hardwareInterface>hardware_interface/EffortJointInterface</hardwareInterface>
      </joint>
      <actuator name="left_front_axle_act">
        <mechanicalReduction>1</mechanicalReduction>
      </actuator>
    </transmission>

    <link name="left_front_wheel">
      <visual>
        <origin rpy="0 0 0" xyz="0 0 0"/>
        <geometry>
          <mesh filename="package://qcar_description/meshes/QCarWheel.stl" scale="0.001 0.001 0.001"/>
        </geometry>
        <material name="red"/>
      </visual>
      <collision>
        <origin rpy="0 0 0" xyz="0 0 0"/>
        <geometry>
          <mesh filename="package://qcar_description/meshes/QCarWheel.stl" scale="0.001 0.001 0.001"/>
        </geometry>
      </collision>
      <xacro:thick_walled_tube_inertial
        inner_rad="${hub_dia / 2}" outer_rad="${tire_dia / 2}"
        height="${tire_width}" mass="${wheel_mass}"/>
    </link>



<!-- ___base_link - > right_front_position_joint (fixed) -> right_steering_link -> right_steering_joint(revolote) -> right_front_axle_carrier -> right_front_axle(joint) (continuous) -> right_front_wheel_______________ -->


    <!-- Front-right assembly -->


    <joint name="right_front_position_joint" type="fixed">
      <parent link="base"/>
      <child link="right_steering_link"/>
      <origin rpy="0 0 0" xyz="0.12960 -0.05590 0.03338"/>
    </joint>

    <link name="right_steering_link">
      <xacro:null_inertial/>
      <visual>
        <origin rpy="0 0 3.14" xyz="0 0 0"/>
        <geometry>
          <mesh filename="package://qcar_description/meshes/QCarSteeringHubL.stl" scale="0.001 0.001 0.001"/>
        </geometry>
        <material name="orange"/>
      </visual>
      <collision>
        <origin rpy="0 0 0" xyz="0 0 0"/>
        <geometry>
          <mesh filename="package://qcar_description/meshes/QCarSteeringHubL.stl" scale="0.001 0.001 0.001"/>
        </geometry>
      </collision>
    </link>

    <joint name="right_steering_joint" type="revolute">
      <parent link="right_steering_link"/>
      <child link="right_front_axle_carrier"/>
      <axis xyz="0 0 1"/>
      <limit lower="-0.523599" upper="0.523599" effort="0.5649" velocity="4.553"/>
    </joint>


    <link name="right_front_axle_carrier">
      <xacro:null_inertial/>
    </link>
    <joint name="right_front_axle" type="continuous">
      <parent link="right_front_axle_carrier"/>
      <child link="right_front_wheel"/>
      <axis xyz="0 1 0"/>
      <limit effort="5.12766" velocity="244.8696"/>
      <dynamics damping="0.1" friction="0.1"/>
    </joint>
    <transmission name="right_front_axle_trans">
      <type>transmission_interface/SimpleTransmission</type>
      <joint name="right_front_axle">
        <hardwareInterface>hardware_interface/EffortJointInterface</hardwareInterface>
      </joint>
      <actuator name="right_front_axle_act">
        <mechanicalReduction>1</mechanicalReduction>
      </actuator>
    </transmission>



    <link name="right_front_wheel">
      <visual>
        <origin rpy="0 0 0" xyz="0 0 0"/>
        <geometry>
          <mesh filename="package://qcar_description/meshes/QCarWheel.stl" scale="0.001 0.001 0.001"/>
        </geometry>
        <material name="red"/>
      </visual>
      <collision>
        <origin rpy="0 0 0" xyz="0 0 0"/>
        <geometry>
          <mesh filename="package://qcar_description/meshes/QCarWheel.stl" scale="0.001 0.001 0.001"/>
        </geometry>
      </collision>
      <xacro:thick_walled_tube_inertial
        inner_rad="${hub_dia / 2}" outer_rad="${tire_dia / 2}"
        height="${tire_width}" mass="${wheel_mass}"/>
    </link>

 


    

    <transmission name="right_steering_trans">
      <type>transmission_interface/SimpleTransmission</type>
      <joint name="right_steering_joint">
        <hardwareInterface>hardware_interface/EffortJointInterface</hardwareInterface>
      </joint>
      <actuator name="right_steering_act">
        <mechanicalReduction>1</mechanicalReduction>
      </actuator>
    </transmission>

    <!-- Rear-left -->
    <link name="left_rear_axle_carrier">
      <xacro:null_inertial/>
    </link>
    <joint name="left_rear_axle" type="continuous">
      <parent link="left_rear_axle_carrier"/>
      <child link="left_rear_wheel"/>
      <axis xyz="0 -1 0"/>
      <origin rpy="0 0 3.14159"/>
      <dynamics damping="0.1" friction="0.1"/>
    </joint>




    <link name="left_rear_wheel">
      <visual>
        <origin rpy="0 0 0" xyz="0 0 0"/>
        <geometry>
          <mesh filename="package://qcar_description/meshes/QCarWheel.stl" scale="0.001 0.001 0.001"/>
        </geometry>
        <material name="red"/>
      </visual>
      <collision>
        <origin rpy="0 0 0" xyz="0 0 0"/>
        <geometry>
          <mesh filename="package://qcar_description/meshes/QCarWheel.stl" scale="0.001 0.001 0.001"/>
        </geometry>
      </collision>
      <xacro:thick_walled_tube_inertial
        inner_rad="${hub_dia / 2}" outer_rad="${tire_dia / 2}"
        height="${tire_width}" mass="${wheel_mass}"/>
    </link>

    <joint name="left_rear_position_joint" type="fixed">
      <parent link="base"/>
      <child link="left_rear_axle_carrier"/>
      <origin rpy="0 0 0" xyz="-0.12765 0.05610 0.03338"/>
    </joint>

    <!-- Rear-right -->
    <link name="right_rear_axle_carrier">
      <xacro:null_inertial/>
    </link>
    <joint name="right_rear_axle" type="continuous">
      <parent link="right_rear_axle_carrier"/>
      <child link="right_rear_wheel"/>
      <axis xyz="0 1 0"/>
      <dynamics damping="0.1" friction="0.1"/>
    </joint>
    <link name="right_rear_wheel">
      <visual>
        <origin rpy="0 0 0" xyz="0 0 0"/>
        <geometry>
          <mesh filename="package://qcar_description/meshes/QCarWheel.stl" scale="0.001 0.001 0.001"/>
        </geometry>
        <material name="red"/>
      </visual>
      <collision>
        <origin rpy="0 0 0" xyz="0 0 0"/>
        <geometry>
          <mesh filename="package://qcar_description/meshes/QCarWheel.stl" scale="0.001 0.001 0.001"/>
        </geometry>
      </collision>
      <xacro:thick_walled_tube_inertial
        inner_rad="${hub_dia / 2}" outer_rad="${tire_dia / 2}"
        height="${tire_width}" mass="${wheel_mass}"/>
    </link>

    <joint name="right_rear_position_joint" type="fixed">
      <parent link="base"/>
      <child link="right_rear_axle_carrier"/>
      <origin rpy="0 0 0" xyz="-0.12765 -0.05610 0.03338"/>
    </joint>

    <!-- (gazebo plugins commented out) -->
  </xacro:macro>

  <!-- IMPORTANT: Instantiate the macro so the robot actually appears -->
  <xacro:QCar prefix="">
    <origin xyz="0 0 0" rpy="0 0 0"/>
  </xacro:QCar>
</robot>
